<?xml version="1.0" encoding="utf-8"?>
<!-- This URDF was automatically created by SolidWorks to URDF Exporter! Originally created by Stephen Brawner (brawner@gmail.com) 
     Commit Version: 1.6.0-4-g7f85cfe  Build Version: 1.6.7995.38578
     For more information, please see http://wiki.ros.org/sw_urdf_exporter -->
<robot
  name="mockup" xmlns:xacro="http://ros.org/wiki/xacro">
  
  <xacro:include filename="$(find robot_model_pkg)/urdf/robot.gazebo.xacro" /> 

  <link name="dummy"> 
  </link>
  <joint name="dummy_joint" type="fixed">
     <parent link="dummy"/>
     <child link="base_link"/>
     <origin rpy="0 0 0" xyz="0 0 0"/>  
  </joint>
  <link
    name="base_link">
    <inertial>
      <origin
        xyz="0.0904702080747973 0.130510056782425 0.0317345302542495"
        rpy="0 0 0" />
      <mass
        value="0.928302977473542" />
      <inertia
        ixx="0.00181610571238853"
        ixy="-3.14209393922838E-07"
        ixz="3.25779536545692E-08"
        iyy="0.00118345617589198"
        iyz="1.03803388385665E-07"
        izz="0.00267462603004712" />
    </inertial>
    <visual>
      <origin
        xyz="0 0 0"
        rpy="0 0 0" />
      <geometry>
        <mesh
          filename="package://robot_model_pkg/meshes/base_link.STL" />
      </geometry>
      <material
        name="">
        <color
          rgba="0.964705882352941 0.964705882352941 0.952941176470588 1" />
      </material>
    </visual>
    <collision>
      <origin
        xyz="0 0 0"
        rpy="0 0 0" />
      <geometry>
        <mesh
          filename="package://robot_model_pkg/meshes/base_link.STL" />
      </geometry>
    </collision>
  </link>
  <link
    name="link_1">
    <inertial>
      <origin
        xyz="-0.080802 0.0010653 -0.016188"
        rpy="0 0 0" />
      <mass
        value="0.14634" />
      <inertia
        ixx="4.563E-05"
        ixy="1.3166E-07"
        ixz="-6.51E-08"
        iyy="0.00018838"
        iyz="-2.4306E-08"
        izz="0.00016163" />
    </inertial>
    <visual>
      <origin
        xyz="0 0 0"
        rpy="0 0 0" />
      <geometry>
        <mesh
          filename="package://robot_model_pkg/meshes/link_1.STL" />
      </geometry>
      <material
        name="">
        <color
          rgba="0.79216 0.81961 0.93333 1" />
      </material>
    </visual>
    <collision>
      <origin
        xyz="0 0 0"
        rpy="0 0 0" />
      <geometry>
        <mesh
          filename="package://robot_model_pkg/meshes/link_1.STL" />
      </geometry>
    </collision>
  </link>
  <joint
    name="joint_1"
    type="revolute">
    <origin
      xyz="0.10489 -0.0758 0.25784"
      rpy="-1.5708 -1.2915 0" />
    <parent
      link="base_link" />
    <child
      link="link_1" />
    <axis
      xyz="0 0 0" />
    <limit
      lower="-3.14"
      upper="3.14"
      effort="100"
      velocity="1" />
  </joint>
  <link
    name="link_2">
    <inertial>
      <origin
        xyz="0.113545597524012 0.474509855148572 0.119784028330441"
        rpy="0 0 0" />
      <mass
        value="0.0784116932589274" />
      <inertia
        ixx="0.000124536944888649"
        ixy="4.06133088041699E-09"
        ixz="-6.50247382107134E-10"
        iyy="8.78739717059435E-06"
        iyz="2.9466015885576E-06"
        izz="0.000123196920844073" />
    </inertial>
    <visual>
      <origin
        xyz="0 0 0"
        rpy="0 0 0" />
      <geometry>
        <mesh
          filename="package://robot_model_pkg/meshes/link_2.STL" />
      </geometry>
      <material
        name="">
        <color
          rgba="0.701960784313725 0.701960784313725 0.701960784313725 1" />
      </material>
    </visual>
    <collision>
      <origin
        xyz="0 0 0"
        rpy="0 0 0" />
      <geometry>
        <mesh
          filename="package://robot_model_pkg/meshes/link_2.STL" />
      </geometry>
    </collision>
  </link>
  <joint
    name="joint_2"
    type="revolute">
    <origin
      xyz="-0.56496 0.088574 -0.0099369"
      rpy="-0.43633 0 -1.5708" />
    <parent
      link="link_1" />
    <child
      link="link_2" />
    <axis
      xyz="0 0 0" />
    <limit
      lower="-3.14"
      upper="3.14"
      effort="100"
      velocity="1" />
  </joint>
  <link
    name="link_3">
    <inertial>
      <origin
        xyz="0.017249 0.014155 0.0020148"
        rpy="0 0 0" />
      <mass
        value="0.0078088" />
      <inertia
        ixx="2.7256E-06"
        ixy="1.7588E-08"
        ixz="3.9578E-10"
        iyy="3.0591E-07"
        iyz="1.4279E-10"
        izz="3.0103E-06" />
    </inertial>
    <visual>
      <origin
        xyz="0 0 0"
        rpy="0 0 0" />
      <geometry>
        <mesh
          filename="package://robot_model_pkg/meshes/link_3.STL" />
      </geometry>
      <material
        name="">
        <color
          rgba="0.96471 0.96471 0.95294 1" />
      </material>
    </visual>
    <collision>
      <origin
        xyz="0 0 0"
        rpy="0 0 0" />
      <geometry>
        <mesh
          filename="package://robot_model_pkg/meshes/link_3.STL" />
      </geometry>
    </collision>
  </link>
  <joint
    name="joint_3"
    type="revolute">
    <origin
      xyz="0.129 0.5285 0.11523"
      rpy="-1.5708 1.1283 -1.5708" />
    <parent
      link="link_2" />
    <child
      link="link_3" />
    <axis
      xyz="0 0 0" />
    <limit
      lower="-1"
      upper="1"
      effort="100"
      velocity="1" />
  </joint>
  <link
    name="link_4">
    <inertial>
      <origin
        xyz="0.00953761532679706 0.0168818886089965 0.0019851684839203"
        rpy="0 0 0" />
      <mass
        value="0.00778649569214158" />
      <inertia
        ixx="2.68264008524836E-06"
        ixy="-2.97896363896993E-07"
        ixz="3.75846368252889E-10"
        iyy="3.43783185444972E-07"
        iyz="-1.89418297478716E-10"
        izz="3.00525807992474E-06" />
    </inertial>
    <visual>
      <origin
        xyz="0 0 0"
        rpy="0 0 0" />
      <geometry>
        <mesh
          filename="package://robot_model_pkg/meshes/link_4.STL" />
      </geometry>
      <material
        name="">
        <color
          rgba="0.964705882352941 0.964705882352941 0.952941176470588 1" />
      </material>
    </visual>
    <collision>
      <origin
        xyz="0 0 0"
        rpy="0 0 0" />
      <geometry>
        <mesh
          filename="package://robot_model_pkg/meshes/link_4.STL" />
      </geometry>
    </collision>
  </link>
  <joint
    name="joint_4"
    type="revolute">
    <origin
      xyz="0.129 0.56346 0.14322"
      rpy="-1.5708 0.58726 -1.5708" />
    <parent
      link="link_2" />
    <child
      link="link_4" />
    <axis
      xyz="0 0 0" />
    <limit
      lower="-1"
      upper="1"
      effort="100"
      velocity="1" />
  </joint>
  <link
    name="pusher_Link">
    <inertial>
      <origin
        xyz="0.12343 0.04438 0.0083134"
        rpy="0 0 0" />
      <mass
        value="0.072201" />
      <inertia
        ixx="0.00013796"
        ixy="-2.6708E-05"
        ixz="-6.8721E-07"
        iyy="0.00018094"
        iyz="-9.4172E-07"
        izz="0.00015743" />
    </inertial>
    <visual>
      <origin
        xyz="0 0 0"
        rpy="0 0 0" />
      <geometry>
        <mesh
          filename="package://robot_model_pkg/meshes/pusher_Link.STL" />
      </geometry>
      <material
        name="">
        <color
          rgba="0.70196 0.70196 0.70196 1" />
      </material>
    </visual>
    <collision>
      <origin
        xyz="0 0 0"
        rpy="0 0 0" />
      <geometry>
        <mesh
          filename="package://robot_model_pkg/meshes/pusher_Link.STL" />
      </geometry>
    </collision>
  </link>
  <joint
    name="pusher_joint"
    type="revolute">
    <origin
      xyz="0.093659 -0.083 0.039201"
      rpy="1.5708 -0.20329 -1.5708" />
    <parent
      link="base_link" />
    <child
      link="pusher_Link" />
    <axis
      xyz="0 0 -1" />
    <limit
      lower="0"
      upper="2.4"
      effort="100"
      velocity="1" />
  </joint>
  <link
    name="wheel_rb_Link">
    <inertial>
      <origin
        xyz="6.1282E-05 -3.5381E-05 0.0067688"
        rpy="0 0 0" />
      <mass
        value="0.088831" />
      <inertia
        ixx="4.3347E-05"
        ixy="1.0649E-07"
        ixz="-1.759E-08"
        iyy="4.347E-05"
        iyz="1.0156E-08"
        izz="6.0223E-05" />
    </inertial>
    <visual>
      <origin
        xyz="0 0 0"
        rpy="0 0 0" />
      <geometry>
        <mesh
          filename="package://robot_model_pkg/meshes/wheel_rb_Link.STL" />
      </geometry>
      <material
        name="">
        <color
          rgba="0.70196 0.70196 0.70196 1" />
      </material>
    </visual>
    <collision>
      <origin
        xyz="0 0 0"
        rpy="0 0 0" />
      <geometry>
        <mesh
          filename="package://robot_model_pkg/meshes/wheel_rb_Link.STL" />
      </geometry>
    </collision>
  </link>
  <joint
    name="wheel_rb_joint"
    type="continuous">
    <origin
      xyz="-0.018701151790293 -0.0290000000000009 0.224033817740037"
      rpy="3.14159265358979 1.5707963267949 0" />
    <parent
      link="base_link" />
    <child
      link="wheel_rb_Link" />
    <axis
      xyz="0 0 -1" />
  </joint>
  <link
    name="wheel_lb_Link">
    <inertial>
      <origin
        xyz="3.5417E-05 -6.1262E-05 -0.0067688"
        rpy="0 0 0" />
      <mass
        value="0.088831" />
      <inertia
        ixx="4.347E-05"
        ixy="1.0656E-07"
        ixz="1.0166E-08"
        iyy="4.3347E-05"
        iyz="-1.7584E-08"
        izz="6.0223E-05" />
    </inertial>
    <visual>
      <origin
        xyz="0 0 0"
        rpy="0 0 0" />
      <geometry>
        <mesh
          filename="package://robot_model_pkg/meshes/wheel_lb_Link.STL" />
      </geometry>
      <material
        name="">
        <color
          rgba="0.70196 0.70196 0.70196 1" />
      </material>
    </visual>
    <collision>
      <origin
        xyz="0 0 0"
        rpy="0 0 0" />
      <geometry>
        <mesh
          filename="package://robot_model_pkg/meshes/wheel_lb_Link.STL" />
      </geometry>
    </collision>
  </link>
  <joint
    name="wheel_lb_joint"
    type="continuous">
    <origin
      xyz="0.198698848209706 -0.0289999999999984 0.224033817740039"
      rpy="3.14159265358979 1.5707963267949 0" />
    <parent
      link="base_link" />
    <child
      link="wheel_lb_Link" />
    <axis
      xyz="0 0 -1" />
  </joint>
  <link
    name="wheel_rf_Link">
    <inertial>
      <origin
        xyz="6.1282E-05 -3.5381E-05 0.0067688"
        rpy="0 0 0" />
      <mass
        value="0.088831" />
      <inertia
        ixx="4.3347E-05"
        ixy="1.0649E-07"
        ixz="-1.759E-08"
        iyy="4.347E-05"
        iyz="1.0156E-08"
        izz="6.0223E-05" />
    </inertial>
    <visual>
      <origin
        xyz="0 0 0"
        rpy="0 0 0" />
      <geometry>
        <mesh
          filename="package://robot_model_pkg/meshes/wheel_rf_Link.STL" />
      </geometry>
      <material
        name="">
        <color
          rgba="0.70196 0.70196 0.70196 1" />
      </material>
    </visual>
    <collision>
      <origin
        xyz="0 0 0"
        rpy="0 0 0" />
      <geometry>
        <mesh
          filename="package://robot_model_pkg/meshes/wheel_rf_Link.STL" />
      </geometry>
    </collision>
  </link>
  <joint
    name="wheel_rf_joint"
    type="continuous">
    <origin
      xyz="-0.018701151790293 -0.029000000000002 0.0384566177400361"
      rpy="3.14159265358979 1.5707963267949 0" />
    <parent
      link="base_link" />
    <child
      link="wheel_rf_Link" />
    <axis
      xyz="0 0 -1" />
  </joint>
  <link
    name="wheel_lf_Link">
    <inertial>
      <origin
        xyz="-4.8712E-05 -5.1328E-05 -0.0067688"
        rpy="0 0 0" />
      <mass
        value="0.088831" />
      <inertia
        ixx="4.3415E-05"
        ixy="-1.228E-07"
        ixz="-1.3982E-08"
        iyy="4.3402E-05"
        iyz="-1.4733E-08"
        izz="6.0223E-05" />
    </inertial>
    <visual>
      <origin
        xyz="0 0 0"
        rpy="0 0 0" />
      <geometry>
        <mesh
          filename="package://robot_model_pkg/meshes/wheel_lf_Link.STL" />
      </geometry>
      <material
        name="">
        <color
          rgba="0.70196 0.70196 0.70196 1" />
      </material>
    </visual>
    <collision>
      <origin
        xyz="0 0 0"
        rpy="0 0 0" />
      <geometry>
        <mesh
          filename="package://robot_model_pkg/meshes/wheel_lf_Link.STL" />
      </geometry>
    </collision>
  </link>
  <joint
    name="wheel_lf_joint"
    type="continuous">
    <origin
      xyz="0.198698848209707 -0.0290000000000011 0.0384566177400396"
      rpy="3.14159265358979 1.5707963267949 0" />
    <parent
      link="base_link" />
    <child
      link="wheel_lf_Link" />
    <axis
      xyz="0 0 -1" />
  </joint>

  <transmission name="pusher_Link_trans">
    <type>transmission_interface/SimpleTransmission</type>
    <joint name="pusher_joint">
    <hardwareInterface>hardware_interface/PositionJointInterface</hardwareInterface></joint>
    <actuator name="pusher_Link_motor">
    <hardwareInterface>hardware_interface/PositionJointInterface</hardwareInterface> 
      <mechanicalReduction>1</mechanicalReduction>
    </actuator>
  </transmission>
  <transmission name="link_1_trans">
    <type>transmission_interface/SimpleTransmission</type>
    <joint name="joint_1">
    <hardwareInterface>hardware_interface/PositionJointInterface</hardwareInterface></joint>
    <actuator name="link_1_motor">
    <hardwareInterface>hardware_interface/PositionJointInterface</hardwareInterface> 
      <mechanicalReduction>1</mechanicalReduction>
    </actuator>
  </transmission>
  <transmission name="link_2_trans">
    <type>transmission_interface/SimpleTransmission</type>
    <joint name="joint_2">
    <hardwareInterface>hardware_interface/PositionJointInterface</hardwareInterface></joint>
    <actuator name="link_2_motor">
    <hardwareInterface>hardware_interface/PositionJointInterface</hardwareInterface> 
      <mechanicalReduction>1</mechanicalReduction>
    </actuator>
  </transmission>
  <transmission name="link_3_trans">
    <type>transmission_interface/SimpleTransmission</type>
    <joint name="joint_3">
    <hardwareInterface>hardware_interface/PositionJointInterface</hardwareInterface></joint>
    <actuator name="link_3_motor">
    <hardwareInterface>hardware_interface/PositionJointInterface</hardwareInterface> 
      <mechanicalReduction>1</mechanicalReduction>
    </actuator>
  </transmission>
    <transmission name="link_4_trans">
    <type>transmission_interface/SimpleTransmission</type>
    <joint name="joint_4">
    <hardwareInterface>hardware_interface/PositionJointInterface</hardwareInterface></joint>
    <actuator name="link_4_motor">
    <hardwareInterface>hardware_interface/PositionJointInterface</hardwareInterface> 
      <mechanicalReduction>1</mechanicalReduction>
    </actuator>
  </transmission>

  <gazebo>
    <plugin name="control" filename="libgazebo_ros_control.so">
      <robotNamespace>/</robotNamespace>
    </plugin>
  </gazebo>

  <gazebo reference="pusher_Link">
    <selfCollide>true</selfCollide>
  </gazebo>
  <gazebo reference="link_1">
    <selfCollide>true</selfCollide>
  </gazebo>
  <gazebo reference="link_2">
    <selfCollide>true</selfCollide>
  </gazebo>
  <gazebo reference="link_3">
    <selfCollide>true</selfCollide>
  </gazebo>
  <gazebo reference="link_4">
    <selfCollide>true</selfCollide>

  </gazebo>
</robot>